<mujoco model="balance">

  <worldbody>
    <body name="robot_body">
      <joint name="robot_body_joint" type="free"/>
      <geom size="0.05 0.0185 0.0855" pos="0 0 0.0995" type="box"/>
      <inertial pos="0 0.0 0.057" mass="0.514" />

      <body name="l_wheel" pos="-0.074 0 0.034">
        <inertial pos="0 0 0" mass="0.032"/>
        <joint name="torso_l_wheel" type="hinge" pos="0 0 0" axis="-1 0 0" damping="0.01"/>
        <geom name="l_wheel_geom" size="0.034 0.013" quat="0.707107 0 0.707107 0" type="cylinder"  material="wheel_material"/>
      </body>
      <body name="r_wheel" pos="0.074 0 0.034">
        <inertial pos="0 0 0" mass="0.032"/>
        <joint name="torso_r_wheel" type="hinge" pos="0 0 0" axis="1 0 0" damping="0.01"/>
        <geom name="r_wheel_geom" size="0.034 0.013" quat="0.707107 0 0.707107 0" type="cylinder" material="wheel_material"/>
      </body>
    </body>
  </worldbody>

  <actuator>
    <velocity name="motor_l_wheel" joint="torso_l_wheel" ctrllimited="true" ctrlrange="-78.54 78.54" kv="4.0" forcelimited="true" forcerange="-0.65 0.65"/>
    <velocity name="motor_r_wheel" joint="torso_r_wheel" ctrllimited="true" ctrlrange="-78.54 78.54" kv="4.0" forcelimited="true" forcerange="-0.65 0.65"/>
  </actuator>

</mujoco>
